<?xml version="1.0" ?>
<!-- =================================================================================== -->
<!-- |    This document was autogenerated by xacro from interaction_robot.xacro        | -->
<!-- |    EDITING THIS FILE BY HAND IS NOT RECOMMENDED                                 | -->
<!-- =================================================================================== -->
<!-- Revolute-Revolute Manipulator -->
<robot name="interaction_robot" xmlns:xacro="http://www.ros.org/wiki/xacro">
  <material name="black">
    <color rgba="0.0 0.0 0.0 1.0"/>
  </material>
  <material name="blue">
    <color rgba="0.0 0.0 0.8 1.0"/>
  </material>
  <material name="green">
    <color rgba="0.0 0.8 0.0 1.0"/>
  </material>
  <material name="grey">
    <color rgba="0.2 0.2 0.2 1.0"/>
  </material>
  <material name="orange">
    <color rgba="1.0 0.423529411765 0.0392156862745 1.0"/>
  </material>
  <material name="brown">
    <color rgba="0.870588235294 0.811764705882 0.764705882353 1.0"/>
  </material>
  <material name="red">
    <color rgba="0.8 0.0 0.0 1.0"/>
  </material>
  <material name="white">
    <color rgba="1.0 1.0 1.0 1.0"/>
  </material>
  <!-- ros_control plugin -->
  <gazebo>
    <plugin filename="libgazebo_ros_control.so" name="gazebo_ros_control">
      <robotSimType>icart_mini_gazebo/ICartMiniHWSim</robotSimType>
    </plugin>
  </gazebo>
  <!-- Left Wheel -->
  <gazebo reference="left_wheel">
    <mu1>1.0</mu1>
    <mu2>1.0</mu2>
    <kp>1000000.0</kp>
    <kd>100.0</kd>
    <minDepth>0.001</minDepth>
    <maxVel>1.0</maxVel>
    <material>Gazebo/Orange</material>
  </gazebo>
  <!-- Base Link -->
  <gazebo reference="base_link">
    <material>Gazebo/White</material>
  </gazebo>
  <!-- Right Wheel -->
  <gazebo reference="right_wheel">
    <mu1>1.0</mu1>
    <mu2>1.0</mu2>
    <kp>1000000.0</kp>
    <kd>100.0</kd>
    <minDepth>0.001</minDepth>
    <maxVel>1.0</maxVel>
    <material>Gazebo/Orange</material>
  </gazebo>
  <!-- <xacro:include filename="$(find icart_mini_description)/urdf/sensors/imu.urdf.xacro"/>
  <xacro:sensor_imu name="imu" parent="base_link" size="0.05 0.05 0.05">
      <origin xyz="0.04 0.0 0.15" rpy="0 0 3.14"/>
  </xacro:sensor_imu> -->
  <!-- Base Link -->
  <link name="base_link">
    <collision>
      <origin rpy="0 0 0" xyz="0 0 0.15"/>
      <geometry>
        <box size=".645 .385 .02"/>
      </geometry>
    </collision>
    <visual>
      <origin rpy="0 0 0" xyz="0 0 0.15"/>
      <geometry>
        <box size=".64 .385 .02"/>
      </geometry>
      <material name="orange"/>
    </visual>
    <collision>
      <origin rpy="0 0 0" xyz="0.02 0 0.81"/>
      <geometry>
        <box size=".020 .040 1.30"/>
      </geometry>
    </collision>
    <visual>
      <origin rpy="0 0 0" xyz="0.02 0 0.81"/>
      <geometry>
        <box size=".020 .040 1.30"/>
      </geometry>
      <material name="orange"/>
    </visual>
    <collision name="collision">
      <origin rpy="0 1.5707 1.5707" xyz="-0.185 -0.0875 0.05"/>
      <geometry>
        <cylinder length="0.03" radius="0.04625"/>
      </geometry>
    </collision>
    <visual name="visual">
      <origin rpy="0 1.5707 1.5707" xyz="-0.185 -0.0875 0.05"/>
      <geometry>
        <cylinder length="0.03" radius="0.04625"/>
      </geometry>
    </visual>
    <collision name="collision">
      <origin rpy="0 1.5707 1.5707" xyz="-0.185 0.0875 0.05"/>
      <geometry>
        <cylinder length="0.03" radius="0.04625"/>
      </geometry>
    </collision>
    <visual name="visual">
      <origin rpy="0 1.5707 1.5707" xyz="-0.185 0.0875 0.05"/>
      <geometry>
        <cylinder length="0.03" radius="0.04625"/>
      </geometry>
    </visual>
    <collision name="collision">
      <origin rpy="0 1.5707 1.5707" xyz="0.18 -0.0875 0.05"/>
      <geometry>
        <cylinder length="0.03" radius="0.04625"/>
      </geometry>
    </collision>
    <visual name="visual">
      <origin rpy="0 1.5707 1.5707" xyz="0.18 -0.0875 0.05"/>
      <geometry>
        <cylinder length="0.03" radius="0.04625"/>
      </geometry>
    </visual>
    <collision name="collision">
      <origin rpy="0 1.5707 1.5707" xyz="0.18 0.0875 0.05"/>
      <geometry>
        <cylinder length="0.03" radius="0.04625"/>
      </geometry>
    </collision>
    <visual name="visual">
      <origin rpy="0 1.5707 1.5707" xyz="0.18 0.0875 0.05"/>
      <geometry>
        <cylinder length="0.03" radius="0.04625"/>
      </geometry>
    </visual>
    <inertial>
      <mass value="20"/>
      <origin rpy="0 0 0" xyz="0 0 0"/>
      <inertia ixx="1" ixy="0" ixz="0" iyy="1" iyz="0" izz="1"/>
    </inertial>
  </link>
  <link name="visual_left_wheel">
    <visual name="visual">
      <origin rpy="0 1.5707 1.5707" xyz="0 0 0"/>
      <geometry>
        <cylinder length="0.03" radius="0.0725"/>
      </geometry>
    </visual>
  </link>
  <joint name="visual_left_wheel_hinge" type="fixed">
    <origin rpy="0 0 0" xyz="0 0.15 0.0725"/>
    <child link="visual_left_wheel">visual_left_wheel</child>
    <parent link="base_link">base_link</parent>
    <axis xyz="0 1 0"/>
  </joint>
  <link name="left_wheel">
    <collision name="collision">
      <origin rpy="0 1.5707 1.5707" xyz="0 -0 0"/>
      <geometry>
        <cylinder length="0.03" radius="0.0725"/>
      </geometry>
    </collision>
    <!--visual name="visual">
      <origin xyz="0 0.0 0" rpy="0 1.5707 1.5707"/>
      <geometry>
        <cylinder  length="0.03" radius="0.0725"/>
      </geometry>
    </visual-->
    <inertial>
      <mass value="1"/>
      <origin xyz="0 0.0 0"/>
      <inertia ixx="0.1" ixy="0" ixz="0" iyy="0.1" iyz="0" izz="0.1"/>
    </inertial>
  </link>
  <joint name="left_wheel_hinge" type="revolute">
    <origin rpy="0 0 0" xyz="0 0.15 0.07258"/>
    <child link="left_wheel">left_wheel</child>
    <parent link="base_link">base_link</parent>
    <axis xyz="0 1 0"/>
    <limit effort="100" lower="-5000" upper="5000" velocity="100.0"/>
  </joint>
  <link name="visual_right_wheel">
    <visual name="visual">
      <origin rpy="0 1.5707 1.5707" xyz="0 -0 0"/>
      <geometry>
        <cylinder length="0.03" radius="0.0725"/>
      </geometry>
    </visual>
  </link>
  <joint name="visual_right_wheel_hinge" type="fixed">
    <origin rpy="0 0 0" xyz="0 -0.15 0.0725"/>
    <child link="visual_right_wheel">visual_right_wheel</child>
    <parent link="base_link">base_link</parent>
    <axis xyz="0 1 0"/>
  </joint>
  <link name="right_wheel">
    <collision name="collision">
      <origin rpy="0 1.5707 1.5707" xyz="0 -0 0"/>
      <geometry>
        <cylinder length="0.03" radius="0.0725"/>
      </geometry>
    </collision>
    <!--visual name="visual">
      <origin xyz="0 0.0 0" rpy="0 1.5707 1.5707"/>
      <geometry>
        <cylinder  length="0.03" radius="0.0725"/>
      </geometry>
    </visual-->
    <inertial>
      <mass value="1"/>
      <origin xyz="0 0.0 0"/>
      <inertia ixx="0.1" ixy="0" ixz="0" iyy="0.1" iyz="0" izz="0.1"/>
    </inertial>
  </link>
  <joint name="right_wheel_hinge" type="revolute">
    <origin rpy="0 0 0" xyz="0 -0.15 0.0725"/>
    <child link="right_wheel">right_wheel</child>
    <parent link="base_link">base_link</parent>
    <axis xyz="0 1 0"/>
    <limit effort="100" lower="-5000" upper="5000" velocity="100.0"/>
  </joint>
  <transmission name="tran1">
    <type>transmission_interface/SimpleTransmission</type>
    <joint name="left_wheel_hinge">
      <hardwareInterface>VelocityJointInterface</hardwareInterface>
    </joint>
    <actuator name="left_motor">
      <hardwareInterface>VelocityJointInterface</hardwareInterface>
      <mechanicalReduction>1</mechanicalReduction>
    </actuator>
  </transmission>
  <transmission name="tran2">
    <type>transmission_interface/SimpleTransmission</type>
    <joint name="right_wheel_hinge">
      <hardwareInterface>VelocityJointInterface</hardwareInterface>
    </joint>
    <actuator name="right_motor">
      <hardwareInterface>VelocityJointInterface</hardwareInterface>
      <mechanicalReduction>1</mechanicalReduction>
    </actuator>
  </transmission>
  <!-- arm -->
  <joint name="arm_base_joint" type="fixed">
    <parent link="base_link"/>
    <child link="arm_base"/>
    <origin rpy="0 0 0" xyz="0.055 0.0 1.06"/>
  </joint>
  <link name="arm_base">
    <visual name="visual">
      <origin rpy="0 0 0" xyz="0.0 0 0.0"/>
      <geometry>
        <box size=".05 .07 .09"/>
      </geometry>
    </visual>
  </link>
  <joint name="arm_joint_0" type="revolute">
    <parent link="arm_base"/>
    <child link="arm_link_1"/>
    <origin rpy="0 0 0" xyz="0.025 0.0 0.035"/>
    <axis rpy="0 0 0" xyz="1 0 0"/>
    <limit effort="100" lower="-1.5" upper="1.5" velocity="100.0"/>
  </joint>
  <link name="arm_link_1">
    <visual name="visual">
      <origin rpy="0 0 0" xyz="0.035 0 0.0"/>
      <geometry>
        <box size="0.07 0.04 0.04"/>
      </geometry>
    </visual>
  </link>
  <joint name="arm_joint_1" type="revolute">
    <parent link="arm_link_1"/>
    <child link="arm_link_2"/>
    <origin rpy="0 0 0" xyz="0.05 0.0 0.0"/>
    <axis rpy="0 0 0" xyz="0 0 1"/>
    <limit effort="100" lower="-1.5" upper="1.5" velocity="100.0"/>
  </joint>
  <link name="arm_link_2">
    <visual name="visual">
      <origin rpy="0 0 0" xyz="0.04 0 0"/>
      <geometry>
        <box size="0.08 0.06 0.06"/>
      </geometry>
    </visual>
  </link>
  <joint name="arm_joint_2" type="revolute">
    <parent link="arm_link_2"/>
    <child link="arm_link_3"/>
    <origin rpy="0 0 0" xyz="0.05 0.0 0.0"/>
    <axis rpy="0 0 -1.57" xyz="0 1 0"/>
    <limit effort="100" lower="-3.14" upper="0" velocity="100.0"/>
  </joint>
  <link name="arm_link_3">
    <visual name="visual">
      <origin rpy="0 0 0" xyz="0.0 0. -0.13"/>
      <geometry>
        <box size="0.05 0.05 0.28"/>
      </geometry>
    </visual>
  </link>
  <joint name="arm_joint_3" type="revolute">
    <parent link="arm_link_3"/>
    <child link="arm_link_4"/>
    <origin rpy="0 0 3.14" xyz="0.0 0.0 -0.25"/>
    <axis rpy="0 0 0" xyz="0 1 0"/>
    <limit effort="100" lower="0" upper="3.14" velocity="100.0"/>
  </joint>
  <link name="arm_link_4">
    <visual name="visual">
      <origin rpy="0 0 0" xyz="0.05 0 -0.13"/>
      <geometry>
        <box size="0.05 0.05 0.25"/>
      </geometry>
    </visual>
  </link>
  <joint name="arm_joint_4" type="revolute">
    <parent link="arm_link_4"/>
    <child link="arm_link_5"/>
    <origin rpy="0 0 3.14" xyz="0.045 0.0 -0.23"/>
    <axis rpy="0 0 0" xyz="0 1 0"/>
    <limit effort="100" lower="-1.57" upper="1.57" velocity="100.0"/>
  </joint>
  <link name="arm_link_5">
    <visual name="visual">
      <origin rpy="0 0 0" xyz="0.0 0 -0.03"/>
      <geometry>
        <box size="0.05 0.05 0.08"/>
      </geometry>
    </visual>
  </link>
  <joint name="arm_joint_5" type="revolute">
    <parent link="arm_link_5"/>
    <child link="arm_link_6"/>
    <origin rpy="0 0 0" xyz="0.0 0.0 -0.06"/>
    <axis rpy="0 0 0" xyz="1 0 0"/>
    <limit effort="100" lower="-1.57" upper="1.57" velocity="100.0"/>
  </joint>
  <link name="arm_link_6">
    <visual name="visual">
      <origin rpy="0 0 0" xyz="0.0 0 -0.04"/>
      <geometry>
        <box size="0.05 0.03 0.05"/>
      </geometry>
    </visual>
  </link>
</robot>

